Workbook
Name UO: #REF!
Name Z_3FBB35F5_DD50_484F_B77F_6029FD8823ED_.wvu.PrintArea: 'Effectif par niveau'!$A$22:$G$40
Name Z_3FBB35F5_DD50_484F_B77F_6029FD8823ED_.wvu.PrintTitles: 'Personnel Région 3 DRH'!$2:$2
Name Z_3FBB35F5_DD50_484F_B77F_6029FD8823ED_.wvu.PrintTitles: 'Personnel Région_1 DRH'!$2:$2
Name Z_3FBB35F5_DD50_484F_B77F_6029FD8823ED_.wvu.PrintTitles: 'Personnel Région_2 DRH'!$2:$2

Sheet Couleurs
A1: Signification des couleurs
C2: Non disponible
C4: Non applicable

Sheet Table des matières
A1: TABLE DES MATIERES
A3: Indicateurs PNDS et ODD | B3: pp 4-5
A4: Synthèse de quelques indicateurs | B4: pp 6-11
A5: Quelques indicateurs économiques | B5: p 12
A6: 1. INFORMATIONS GENERALES
A7: Quelques résultats d'enquête et des CNS | B7: p 14
A8: Indicateurs clés de planification familiale issus de l’enquête PMABF | B8: pp 15-16
A9: Population du Burkina Faso par groupe d'âge | B9: pp 17 - 18
A10: populations cibles par district | B10: pp 19 - 22
A11: Population selon la distance par district | B11: pp 23 - 24
A12: Complétude des rapports des formations sanitaires | B12: pp 25 - 36
A13: 2. ADMINISTRATION ET GESTION
A14: Bilan physique et financier des plans d'ations | B14: pp 38 - 44
A15: Disponibilité des MEG dans les formations sanitaires | B15: pp 45 - 46
A16: Disponibilité des MEG traceurs dans les DRD par régions | B16: pp 47 - 49
A17: Ruptures de stock des 25 medicaments traceurs dans les DMEG témoins/région | B17: p 50
A18: Quleques résultats de la gratuité des soins | B18: pp 51 - 52
A19: 3. RESSOURCES ET INFRASTRUCTURES
A20: Ressources humaines | B20: pp 54 - 67
A21: Infrastructures | B21: pp 68 - 75
A22: Situation des OBC par district | B22: pp 76 - 77
A23: Lits et occupation dans les formations sanitaires | B23: pp 78 - 83
A24: rayon moyen d'action théorique (RMAT) | B24: pp 84 - 85
A25: Ratio habitant/CSPS | B25: pp 86 - 87
A26: 4. ACTIVITES DANS LES FORMATIONS SANITAIRES
A27: Couvertures vaccinales par antigène | B27: pp 89 - 102
A28: Vaccination contre la covid-19 | B28: pp 103 - 104
A29: Activités de santé maternelle et infantile | B29: pp 105 - 162
A30: Prévention de la transmission mère enfant du VIH | B30: pp 163 - 177
A31: Surveillance nutritionnelle et prise en charge de la nutrition | B31: pp 178 - 198
A32: Fréquentation des formations sanitaires, références/contre-références | B32: pp 199 - 271
A33: Paludisme | B33: pp 272 - 297
A34: Infections sexuellement transmissibles (IST) ,dépistage VIH/SIDA et hépatites | B34: pp 298 - 303
A35: File active du VIH et AELB | B35: pp 304 - 308
A36: Tuberculose | B36: pp 309 - 324
A37: MTN | B37: pp 325 - 335
A38: Surveillance épidémiologique | B38: pp 336 - 353
... A47: ANSSEAT | B47: pp 405
A48: 5. ACTIVITES DE SANTE COMMUNAUTAIRE
A49: Situation des ASBC récrutés par district | B49: pp 407 - 408
...

Sheet indicateursPNDS_ODD
A1: Tableau 0.01: indicateurs PNDS et ODD
A2: Indicateurs | B2: 2021 | C2: 2022 | D2: 2023 | E2: 2024 | F2: 2025 | G2: Sources de données | H2: Structure
A3: Ratio de mortalité maternelle pour 100 000 naissances vivantes | G3: Rapport EDS 2021 | H3: DGESS
A4: Taux de mortalité néonatale (‰) | G4: Rapport EDS 2021 | H4: DGESS
A5: Taux de mortalité infantile (‰) | G5: Rapport EDS 2021 | H5: DGESS
A6: Proportion des recommandations du CSD mises en œuvre dans les délais (%) | G6: Rapport CSD | H6: DPPSE
A7: Taux de satisfaction des usagers des services de santé (%) | G7: Rpport HHFA 2020 | H7: DSSE
A8: Proportion des structures ayant une performance globale satisfaisante (%) | G8: Rapport d'évaluation | H8: DDII
A9: Taux de complétude des saisies des rapports d’activités des formations sanitaires privés et publiques de soins | F9: =Complétude!K108 | G9: Annuaire statistique | H9: DSSE
A10: Taux de promptitude des saisies des rapports d’activités des formations sanitaires privés et publiques de soins | F10: =Complétude!M108 | G10: Annuaire statistique | H10: DSSE
A11: Densité des professionnels de santé pour 10 000 habitants | G11: Rpport HHFA 2020 | H11: DSSE
A12: Ratio population/médecin | F12: ='Evolution Effectif personnel'!F13 -> 0 | G12: Annuaire Statistique | H12: DRH
A13: Ratio population /Sage- femme-Maïeuticien | F13: ='Evolution Effectif personnel'!F17 -> 0 | G13: Annuaire Statistique | H13: DRH
A14: Proportion des CMA disposant d’au moins 2 médecins formés en Chirurgie essentielle | G14: Rapports d'activités | H14: DDSS
A15: Dépenses de santé des ménages en % des dépenses courantes de santé | F15: =IF(IndicateursEconomiques!#REF!="","",IndicateursEconomiques!#REF!) -> #REF! | G15: Comptes de santé | H15: DSSE
A16: Nombre de nouveaux contacts par habitant et par an des enfants de moins de 5 ans | F16: ='Nb_nouveau contact'!E107 | G16: Annuaire statistique MS | H16: DSSE
A17: Prévalence contraceptive (chez les femmes en union) (%) | F17: 32 | G17: PMA2020, EDS 2021 | H17: DSSE
A18: Taux de mortalité maternelle intra hospitalière pour 100 000 parturientes | F18: ='Taux de décès maternel'!F107 | G18: Annuaire statistique MS | H18: DSF
A19: Incidence du paludisme confirmé (pour 1000 hbts) | F19: ='Incidence paludisme confirmé'!F107 | G19: Annuaire statistique MS | H19: DSSE
A20: Taux de transmission résiduelle du VIH de la mère à l'enfant (%) | F20: 2.9229407 | G20: Enquête de séroprévalence | H20: PSLSS
A21: Prévalence de la malnutrition aiguë sévère chez les enfants de moins de 5 ans (%) | F21: 0.1 | G21: Rapport ENN | H21: DN
A22: Taux de notification de nouveaux cas de tuberculose toute forme et rechute (pour 100 000 habitants) | F22: ='Notification TB_Dépist TBVIH'!J108 | G22: Annuaire statistique MS | H22: PNT
A23: Part du budget alloué au MS | F23: 11.79 | H23: DGF santé
A24: Part du budget alloué au Secteur Santé | F24: 11.96 | H24: DGF santé
A25: Taux d'exécution des ressources financières (%) | F25: ='Bilan PA _2'!I159 | G25: Bilan des PA | H25: DPPSE
A26: Score moyen de la disponibilité des éléments de la capacité opérationnelle pour les SONUB (%) | G26: Rapport enquête HHFA | H26: DSSE
A27: Proportion de la population vivant à moins de 5 km d’une formation sanitaire (%) | F27: ='Pop_distance '!G108 | G27: Annuaire statistique | H27: DSSE
A28: Pourcentage des DMEG n'ayant pas connu de rupture des 25 molécules traceurs (%) | F28: =Rupture_DMEG!E86 | G28: Annuaire statistique | H28: DGAP
A29: Pourcentage des hôpitaux publics où la pharmacie hospitalière est fonctionnelle (%) | G29: Rapport d'activités DPH | H29: DPH
A30: Proportion des CM/CMA n’ayant pas connu de rupture des examens traceurs (%) | G30: Rapport d'activités | H30: DLBM
A31: Taux de satisfaction des demandes (utilisateurs) en PSL (%) | F31: =+CNTS5!D13 -> 67.593366 | G31: Annuaire statistique CNTS | H31: CNTS
A32: Pourcentage des femmes ayant reçu au moins 3 doses de traitement préventif intermittent pendant les consultations prénatales (%) | F32: ='Couverture CPN'!J107 | G32: Annuaire statistique MS | H32: SP-Palu
A33: Nombre de districts exclus du traitement de la filariose lymphatique | F33: 67 | G33: Annuaire statistique MS | H33: DPSP
A34: Pourcentage de femmes enceintes dépistées positives pour le VIH qui reçoivent un traitement ARV adapté | F34: ='synthèse indicateurs'!F98 -> 0 | G34: Annuaire statistique MS | H34: DSF
A35: Taux de succès aux traitements antituberculeux | F35: ='Traitement TB'!J108 | G35: Annuaire statistique MS | H35: PNT
A36: Pourcentage des femmes de 30 à 49 ans qui ont été soumises à un dépistage du cancer du col de l’utérus par les méthodes appropriées (inspection visuelle après application d’acide acétique/vinaigre et au Lugol (IVA/IVL), frottis (test de Pap), test VPH (virus du papillome humain) (%) | G36: Rapport enquête STEPS | H36: DPCM
A37: Proportion des formations sanitaires mettant en œuvre l’approche WHO-PEN | F37: 21.9 | G37: Rapport d’activités | H37: DSSE
A38: Létalité du paludisme grave chez les enfants de moins de 5 ans | F38: =Palu_létalité!G107 | G38: Annuaire statistique MS | H38: DSSE
A39: Taux de couverture en CPN4 et plus (%) | F39: ='Couverture CPN'!I107 | G39: Annuaire statistique MS | H39: DSSE
A40: Taux de couverture en RR2 (%) | F40: ='Couverture vaccinale2'!J107 | G40: Annuaire statistique MS | H40: DSSE
...

Sheet synthèse indicateurs
A1: Tableau 0.02: Synthèse de quelques indicateurs
A2: Indicateurs | B2: 2021 | C2: 2022 | D2: 2023 | E2: 2024 | F2: 2025
A3: Démographie
A4: Population totale | B4: 21500559 | C4: 22184452 | D4: 22882385 | F4: =Population!F111 -> 0
A5: Population de moins de 5 ans | B5: 3933981 | C5: 4017780 | D5: 4090130 | F5: =Population!C111 -> 0
A6: Infrastructures Publiques
A7: Effectif des CHU | B7: 6 | C7: 6 | D7: 6 | F7: =Infrast_publique!C86 -> 0
A8: Effectif des CHR | B8: 9 | C8: 9 | D8: 9 | F8: =Infrast_publique!D86 -> 0
A9: Effectif des CMA | B9: 46 | C9: 46 | D9: 46 | F9: =Infrast_publique!E86 -> 0
A10: Effectif des CM | B10: 83 | C10: 99 | D10: 116 | F10: =Infrast_publique!F86 -> 0
A11: Effectif des CSPS | B11: 2126 | C11: 2207 | D11: 2233 | F11: =Infrast_publique!G86 -> 0
A12: Effectif des dispensaires isolés | B12: 87 | C12: 51 | D12: 49 | F12: =Infrast_publique!H86 -> 0
A13: Effectif maternités isolées | B13: 8 | C13: 4 | D13: 4 | F13: =Infrast_publique!I86 -> 0
A14: Autres FS publiques (infirmeries, etc) | B14: 201 | C14: 234 | D14: 213 | F14: =Infrast_publique!J86 -> 0
A15: Ratio habitant par CSPS | B15: 10113.151 | C15: 9396.2101 | D15: 9526.3884 | F15: =+Ratio_hbt_Csps!E86 -> #DIV/0!
A16: Rayon d’action moyen théorique en km (sans le privé) | B16: 6.1424756 | C16: 6.0678759 | D16: 6.0158663 | F16: =+RMAT!E86 -> #DIV/0!
A17: Pourcentage des formations sanitaires (CSPS) remplissant les normes minimales en personnel | B17: 89.228598 | C17: 89.669234 | D17: 72.458576 | F17: =+Norme_personnel!E86
A18: Poucentage de la population à plus de 5 km d'une FS | B18: 39.6 | C18: 37.99649 | D18: 36.56589 | F18: =+'Pop_distance '!H108+'Pop_distance '!I108 -> #VALUE!
A19: Infrastructures Privées
A20: Effectif des établissements sanitaires privés de soins hospitaliers* | B20: 208 | C20: 243 | D20: 318 | F20: =SUM(Infrastructure_privées1!C87:H87) -> 0
A21: Effectif des établissements sanitaires privés de soins non hospitaliers** | B21: 530 | C21: 617 | D21: 784 | F21: =Infrastructure_privées2!H87-SUM(Infrastructure_privées1!C87:H87) -> 0
A22: Effectif des officines | B22: 240 | C22: 311 | D22: 313 | F22: =Infrastructure_privées2!I87 -> 0
A23: Effectif des dépots pharmaceutiques privés | B23: 668 | C23: 812 | D23: 830 | F23: =Infrastructure_privées2!J87 -> 0
A24: Rayon d’action moyen théorique en km (y compris le privé) | B24: 5.491138 | C24: 5.3518673 | D24: 5.227606 | F24: =RMAT!G86 -> #DIV/0!
A25: Ressources financières
A26: Total budget ministère de la santé (millions F CFA) | B26: 266080.49 | C26: 301755.92 | D26: 266747.7 | F26: 336392.77
A27: Pourcentage du budget du Ministère de la santé / budget de l'Etat (norme : ≥ 12,7%) | B27: 13.52 | C27: 13.89 | D27: 11.53 | F27: =+indicateursPNDS_ODD!F23 -> 11.79
A28: Part du budget alloué au Secteur Santé (norme : ≥ 15%) | B28: 13.93 | C28: 14.46 | D28: 11.87 | F28: =+indicateursPNDS_ODD!F24 -> 11.96
A29: Taux d'exécution budgetaire du Ministère de la santé (%) | B29: 99.04 | C29: 93.73 | D29: 98.6
A30: Taux d’absorption des ressources financières allouées (%) | B30: 98.71 | C30: 93.26 | D30: 99.36 | F30: =+'Bilan PA _2'!I159
A31: Ressources humaines
A32: Effectif de Médecins | B32: 2226 | C32: 2319 | D32: 2318 | F32: ='Evolution Effectif personnel'!F3 -> 2518
A33: Effectif de Chirurgiens dentistes | B33: 45 | C33: 57 | D33: 55 | F33: ='Effectif par niveau'!H5 -> 40
A34: Effectif de Pharmaciens | B34: 329 | C34: 337 | D34: 317 | F34: ='Effectif par niveau'!H6 -> 379
A35: Effectif d'attaché de santé | B35: 2953 | C35: 3193 | D35: 3292 | F35: ='Effectif par niveau'!H7 -> 3080
A36: Effectif d' Infirmiers diplômés d'Etat (IDE) | B36: 7661 | C36: 7827 | D36: 7592 | F36: ='Effectif par niveau'!H10 -> 4037
A37: Effectif d'Infirmiers brevetés (IB) | B37: 1604 | C37: 1483 | D37: 1325 | F37: ='Effectif par niveau'!H12 -> 690
A38: Effectif de SF/ME | B38: 4847 | C38: 5086 | D38: 4970 | F38: ='Effectif par niveau'!H11 -> 3041
A39: Effectif d'Agents itinérants de santé (AIS) | B39: 2935 | C39: 2887 | D39: 2313 | F39: ='Effectif par niveau'!H19 -> 1021
A40: Effectif des ASBC | B40: 17648 | C40: 24958 | D40: 16785 | F40: ='Situation ASBC'!G87 -> 0
...

Sheet IndicateursEconomiques
A1: Tableau 0.03: Quelques indicateurs économiques
A2: INTITULE | B2: 2021 | C2: 2022 | D2: 2023 | E2: 2024
A3: Indicateurs macroéconomiques
A4: Budget État (millions de FCFA) | B4: 2572988 | C4: 2172097 | D4: 2314412
A5: PIB (millions de FCFA) | B5: 9664699 | C5: 11779465 | D5: 12328298
A6: PIB par habitant (unités de devises locales constantes) | B6: 449581.57 | C6: 494000 | D6: 486700
A7: Croissance PIB (%) | B7: 6.9063417 | C7: 2.7 | D7: 3
A8: Inflation, prix à la consommation (% annuel) | B8: 3.6535329 | C8: 14.3 | D8: 12.8
A9: Dépenses de santé du reste du monde (millions de FCFA) | B9: 129300.93 | C9: 162196.1 | D9: 209900.94
A10: Dépenses de santé de l’État (millions de FCFA) | B10: 298419.63 | C10: 301.75592 | D10: 314903.14
A11: Dépense des salaires payés par l’État (millions de FCFA) | B11: 175 701, 832 | C11: 192404.42 | D11: 199941.61
A12: Dépenses assurance maladie (millions de FCFA) | B12: 10895.24 | C12: 14938.1 | D12: 15788.11
A13: Dépenses de santé du reste du monde en % des dépenses courantes de santé | B13: 18.5 | C13: 20.353827 | D13: 21
A14: Dépenses de santé de l’État en % du budget de l’État | B14: 11.6 | C14: 11 | D14: 13.6
A15: Dépense des salaires payés par l’État en % les dépenses de santé de l’État | B15: 56.3 | C15: 60.01 | D15: 63.5
A16: Dépenses assurance maladie en % dépense totale de santé | B16: 1.5 | C16: 1.7 | D16: 1.5
A17: Dépenses assurance maladie en % dépense de santé des ménages | B17: 4.5 | C17: 5.4 | D17: 3.6
A18: Indicateurs de base des comptes de santé
A19: Dépenses courantes de santé | B19: 697963 | C19: 796882.57 | D19: 1001898
A20: Dépense en Investissement | B20: 27980 | C20: 55974.558 | D20: 35823
A21: Dépense connexe aux Investissement | B21: 2597 | C21: 3987.9865 | D21: 6584
A22: Dépenses Totale en santé (millions de FCFA) | B22: 728541 | C22: 856845.12 | D22: 1044304
A23: Dépenses des ménages (en millions de FCFA) | B23: 243127 | C23: 277819.22 | D23: 440863
A24: Dépenses publiques en santé (en millions de FCFA) | B24: 298420 | C24: 319898.86 | D24: 314903
A25: Dépenses publiques de santé en % des dépenses totales de santé (%) | B25: 0.41 | C25: 37.334502 | D25: 30.2
A26: Dépenses de santé par habitant (FCFA) | B26: 33885 | C26: 38623.677 | D26: 43785
A27: Dépenses de santé en % du PIB | B27: 0.075 | C27: 7.2740582 | D27: 8.5
A28: Dépenses de santé des ménages en % des dépenses courantes de santé | B28: 33.4 | C28: 32.423505 | D28: 44
A29: Dépenses de soins préventifs | B29: 162734 | C29: 174636.65 | D29: 201977
A30: Dépenses de soins curatifs | B30: 326765 | C30: 386856.09 | D30: 503822
... A38: Dep. de vaccination en % des dep. courantes de santé | B38: 0.98 | C38: 1.1782429 | D38: 1.86
A39: Source: Comptes de santé

Sheet Partie 1
A1: 1. INFORMATIONS GENERALES
A2: Quelques résultats d'enquête et des CNS | B2: p 14
A3: Indicateurs clés de planification familiale issus de l’enquête PMABF | B3: pp 15-16
A4: Population du Burkina Faso par groupe d'âge | B4: pp 17 - 18
A5: populations cibles par district | B5: pp 19 - 22
A6: Population selon la distance par district | B6: pp 23 - 24
A7: Complétude des rapports des formations sanitaires | B7: pp 25 - 36

Sheet SARA_QoC_RDQA_CS_HHFA
A1: Tableau 1.01: quelques résultats de l'audit de la qualité des données de routine (RDQA*)
A2: Indicateurs | C2: 2017 | D2: 2018 | E2: 2021 | F2: 2023
A3: Indice de concordance des données du système de routine sur le paludisme (%) | C3: 72.1 | D3: 80.5 | E3: 76.7 | F3: 77.6
A4: Indice de concordance des données du système de routine sur la vaccination(%) | C4: 82.9 | D4: 87 | E4: 92.3 | F4: 92.8
A5: Indice de concordance des données du système de routine sur la CPN (%) | C5: 85.9 | D5: 93.5 | E5: 94.3
A6: Indice de concordance des données du système de routine sur le VIH (%) | C6: 99.7 | D6: 96.6 | E6: 98.9 | F6: 99.4
A7: Indice de concordance des données du système de routine sur la tuberculose (%) | C7: 98.2 | D7: 99.2 | E7: 99.5 | F7: 97.8
A8: *Routine data quality assessment
A9: ** En 2017, les registres de vaccination ont été considérés comme sources de vérification et non les registres de coches
A11: Tableau 1.02: quelques résultats de l'enquête SARA/HHFA*
A12: Indicateurs | E12: 2018 | F12: 2020
A13: Score moyen de la disponibilité des éléments traceurs de la prévention des infections (%) | E13: 73 | F13: 72.2
A14: Score moyen de la disponibilité des éléments traceurs d’aménagement et de confort (%) | E14: 74 | F14: 66.4
A15: Score moyen de la disponibilité des éléments traceurs des équipements essentiels (%) | E15: 84 | F15: 77.66
A16: Score moyen de la disponibilité des éléments traceurs pour le diagnostic (%) | E16: 50 | F16: 54.78
A17: Score moyen de la disponibilité des médicaments essentiels pour la prise en charge d’un certain nombre de pathologies (%) | E17: 29 | F17: 76.3
A18: * service availability and readiness assessment(2018) et HHFA pour 2020
A20: Tableau 1.03: quelques résultats de l'enquête qualité des prestations de soins du paludisme, de la tuberculose et de l’infection à vih (QoC*)
A21: Indicateurs | C21: 2017 | D21: 2020
A22: Indice de la qualité des soins en matière de paludisme (%) | C22: 78.04 | D22: 66.35
A23: Indice de la qualité des soins en matière de tuberculose (%) | C23: 65.4 | D23: 44.77
A24: Indice de la qualité des soins en matière de PTME (%) | C24: 30.9 | D24: 33.88
A25: Indice de la qualité des soins en matière de VIH (%) | C25: 48.3 | D25: 60.87
A26: Source: SARA/HHFA
A27: * Quality of care

Sheet PMABF
A1: Tableau 1.04: Quelques indicateurs clés de planification familiale issus de l’enquête PMABF au Burkina Faso désagrégés par milieu de résidence
B2: Vague 8 | E2: Vague 9
B3: dec 2020 - mars 2021 | E3: 44228
A4: Indicateurs sur la santé reproductive et la contraception | B4: Urbain | C4: Rural | D4: Total | E4: Urbain | F4: Rural | G4: Total
A5: Âge médian au 1er rapport sexuel (chez les 25-49 ans)
A6: Âge médian à la 1ère union (chez les 25-49 ans)
A7: Âge médian à la 1ère naissance (chez les 25-49 ans)
A8: Âge médian à la 1ère utilisation de la contraception (chez les 25-49 ans)
A9: Nombre moyen d'enfants à la première utilisation de la contraception (15-49 ans)
A10: A reçu des informations sur la planification familiale d’un prestataire au cours des 12 derniers mois (%) (15-49 ans)
A11: Exposition aux messages médiatiques sur la PF au cours des mois ayant précédé l’enquête (%) (15-49 ans)
A13: Indicateurs sur l’accès, l’équité, la qualité et le choix des méthodes (Pour les utilisatrices actuelles des méthodes modernes)
B14: Urbain | C14: Rural | D14: Total | E14: Urbain | F14: Rural | G14: Total
A15: A choisi la méthode elle-même ou avec l’aide du partenaire
A16: A obtenu la méthode souhaitée
A17: On lui a parlé d'autres méthodes
A18: A été conseillée sur les effets secondaires
A19: A payé pour les services de PF
A20: Retournerait voir le prestataire et le recommanderait à une amie ou un membre de la famille
A21: A reçu une méthode d’un SPS dans le secteur public
A23: Événements de la vie avant l'âge de 18 ans (% de toutes femmes âgées de 18 à 24 ans) | B23: Urbain | C23: Rural | D23: Total | E23: Urbain | F23: Rural | G23: Total
A25: Mariées
A26: Ayant utilisé une méthode contraceptive
A27: Premier rapport sexuel
A28: Ayant accouché
A30: Indicateurs de planification familiale (parmi les femmes en union) | B30: Urbain | C30: Rural | D30: Total | E30: Urbain | F30: Rural | G30: Total
A31: Taux de prévalence contraceptive – Toutes méthodes (%)
A32: Taux de prévalence contraceptive – Méthodes modernes (%)
A33: Taux de prévalence contraceptive – De longue durée ou permanent (%)
A34: Besoins non satisfaits totaux (%)
A35: Besoins non satisfaits – Pour limiter les naissances (%)
A36: Besoins non satisfaits – Pour espacer les naissances (%)
A37: Demande contraceptive totale (%)
A38: Demande contraceptive satisfaite par des méthodes modernes (%)
A40: Distribution des méthodes modernes actuelles | B40: Urbain | C40: Rural | D40: Total | E40: Urbain | F40: Rural | G40: Total
A41: (parmi les utilisatrices en union)
A42: Stérilisation féminine
A43: Implants
A44: DIU
A45: Injectables-intramusculaire (DMPA-IM)
...

Sheet Population
A1: Tableau 1.05: répartition de la population du Burkina Faso par district et par groupe d'âge en 2025
A2: Régions/ districts | C2: Moins de 5 ans | D2: 5-14 ans | E2: 15 ans et plus | F2: Total
A3: Bankui
B4: CHR Dédougou
B5: DS Boromo
B6: DS Dedougou
B7: DS Solenzo
A8: Djoro
B9: CHR Gaoua
B10: DS Batié
B11: DS Dano
B12: DS Diébougou
B13: DS Gaoua
B14: DS Kampti
A15: Goulmou
B16: CHR Fada N'Gourma
B17: DS Fada
B18: DS Pama
A19: Guiriko
B20: CHU Sanou Souro
B21: DS Dafra
B22: DS Dande
B23: DS Do
B24: DS Hounde
B25: DS Karangasso Vigue
B26: DS Léna
B27: DS N'Dorola
B28: DS Orodara
A29: Kadiogo
B30: CHU Bogodogo
B31: CHU Pédiatrique CDG
B32: CHU Tengandogo
B33: CHU Yalgado
B34: Hôpital Paul VI
B35: Hôpital Saint Camille
B36: Hôpital SCHIPHRA
B37: DS Baskuy
B38: DS Bogodogo
B39: DS Boulmiougou
B40: DS Nongr-Massom
...

Sheet Pop_cible
A1: Tableau 1.06: Effectifs des populations cibles par district en 2025
A2: Régions/ districts | C2: Femmes en Age de procréer | D2: Grossesses attendues | E2: Accouchements attendus | F2: Naissances vivantes attendues | G2: 0 à 11 mois | H2: 6 à 11 Mois | I2: 12 à 59 Mois | J2: Cas attendus de MAM | K2: Cas attendus de MAS | L2: 12 à 23 Mois | M2: Fille de 9ans
A3: Bankui
B4: CHR Dédougou
B5: DS Boromo
B6: DS Dedougou
B7: DS Solenzo
A8: Djoro
B9: CHR Gaoua
B10: DS Batié
B11: DS Dano
B12: DS Diébougou
B13: DS Gaoua
B14: DS Kampti
A15: Goulmou
B16: CHR Fada N'Gourma
B17: DS Fada
B18: DS Pama
A19: Guiriko
B20: CHU Sanou Souro
B21: DS Dafra
B22: DS Dande
B23: DS Do
B24: DS Hounde
B25: DS Karangasso Vigue
B26: DS Léna
B27: DS N'Dorola
B28: DS Orodara
A29: Kadiogo
B30: CHU Bogodogo
B31: CHU Pédiatrique CDG
B32: CHU Tengandogo
B33: CHU Yalgado
B34: Hôpital Paul VI
B35: Hôpital Saint Camille
B36: Hôpital SCHIPHRA
B37: DS Baskuy
B38: DS Bogodogo
B39: DS Boulmiougou
B40: DS Nongr-Massom
...

Sheet Pop_distance 
A1: Tableau 1.07: Répartition de la population selon la distance à la formation sanitaire de référence en 2025
C2: Population totale | D2: Effectif | G2: Proportion (%)
A3: Régions/Districts | D3: 0 à 4 km | E3: 5 à 9 km | F3: 10 km et + | G3: 0 à 4 km | H3: 5 à 9 km | I3: 10 km et + | J3: Vérification
A4: Bankui | C4: =+Population!F3 -> 0 | D4: =SUM(D5:D8) -> 830062 | E4: =SUM(E5:E8) -> 220009 | F4: =SUM(F5:F8) -> 152657 | G4: =IFERROR(D4/$C4*100,"") | H4: =IFERROR(E4/$C4*100,"") | I4: =IFERROR(F4/$C4*100,"") | J4: =IF(C4="","",C4=SUM(D4+E4+F4)) -> FALSE
B5: CHR Dédougou | C5: =+Population!F4 -> 0 | G5: =IFERROR(D5/$C5*100,"") | H5: =IFERROR(E5/$C5*100,"") | I5: =IFERROR(F5/$C5*100,"") | J5: =IF(C5="","",C5=SUM(D5+E5+F5)) -> TRUE
B6: DS Boromo | C6: =+Population!F5 -> 0 | D6: 277565 | E6: 44103 | F6: 27043 | G6: =IFERROR(D6/$C6*100,"") | H6: =IFERROR(E6/$C6*100,"") | I6: =IFERROR(F6/$C6*100,"") | J6: =IF(C6="","",C6=SUM(D6+E6+F6)) -> FALSE
B7: DS Dedougou | C7: =+Population!F6 -> 0 | D7: 282952 | E7: 111627 | F7: 59156 | G7: =IFERROR(D7/$C7*100,"") | H7: =IFERROR(E7/$C7*100,"") | I7: =IFERROR(F7/$C7*100,"") | J7: =IF(C7="","",C7=SUM(D7+E7+F7)) -> FALSE
B8: DS Solenzo | C8: =+Population!F7 -> 0 | D8: 269545 | E8: 64279 | F8: 66458 | G8: =IFERROR(D8/$C8*100,"") | H8: =IFERROR(E8/$C8*100,"") | I8: =IFERROR(F8/$C8*100,"") | J8: =IF(C8="","",C8=SUM(D8+E8+F8)) -> FALSE
A9: Djoro | C9: =+Population!F8 -> 0 | D9: =SUM(D10:D15) -> 455152 | E9: =SUM(E10:E15) -> 358814 | F9: =SUM(F10:F15) -> 214904 | G9: =IFERROR(D9/$C9*100,"") | H9: =IFERROR(E9/$C9*100,"") | I9: =IFERROR(F9/$C9*100,"") | J9: =IF(C9="","",C9=SUM(D9+E9+F9)) -> FALSE
B10: CHR Gaoua | C10: =+Population!F9 -> 0 | G10: =IFERROR(D10/$C10*100,"") | H10: =IFERROR(E10/$C10*100,"") | I10: =IFERROR(F10/$C10*100,"") | J10: =IF(C10="","",C10=SUM(D10+E10+F10)) -> TRUE
B11: DS Batié | C11: =+Population!F10 -> 0 | D11: 33087 | E11: 45937 | F11: 37247 | G11: =IFERROR(D11/$C11*100,"") | H11: =IFERROR(E11/$C11*100,"") | I11: =IFERROR(F11/$C11*100,"") | J11: =IF(C11="","",C11=SUM(D11+E11+F11)) -> FALSE
B12: DS Dano | C12: =+Population!F11 -> 0 | D12: 178091 | E12: 109836 | F12: 23353 | G12: =IFERROR(D12/$C12*100,"") | H12: =IFERROR(E12/$C12*100,"") | I12: =IFERROR(F12/$C12*100,"") | J12: =IF(C12="","",C12=SUM(D12+E12+F12)) -> FALSE
B13: DS Diébougou | C13: =+Population!F12 -> 0 | D13: 72678 | E13: 76534 | F13: 33978 | G13: =IFERROR(D13/$C13*100,"") | H13: =IFERROR(E13/$C13*100,"") | I13: =IFERROR(F13/$C13*100,"") | J13: =IF(C13="","",C13=SUM(D13+E13+F13)) -> FALSE
B14: DS Gaoua | C14: =+Population!F13 -> 0 | D14: 115171 | E14: 81651 | F14: 83313 | G14: =IFERROR(D14/$C14*100,"") | H14: =IFERROR(E14/$C14*100,"") | I14: =IFERROR(F14/$C14*100,"") | J14: =IF(C14="","",C14=SUM(D14+E14+F14)) -> FALSE
B15: DS Kampti | C15: =+Population!F14 -> 0 | D15: 56125 | E15: 44856 | F15: 37013 | G15: =IFERROR(D15/$C15*100,"") | H15: =IFERROR(E15/$C15*100,"") | I15: =IFERROR(F15/$C15*100,"") | J15: =IF(C15="","",C15=SUM(D15+E15+F15)) -> FALSE
A16: Goulmou | C16: =+Population!F15 -> 0 | D16: =SUM(D17:D19) -> 313778 | E16: =SUM(E17:E19) -> 150119 | F16: =SUM(F17:F19) -> 191787 | G16: =IFERROR(D16/$C16*100,"") | H16: =IFERROR(E16/$C16*100,"") | I16: =IFERROR(F16/$C16*100,"") | J16: =IF(C16="","",C16=SUM(D16+E16+F16)) -> FALSE
B17: CHR Fada N'Gourma | G17: =IFERROR(D17/$C17*100,"") | H17: =IFERROR(E17/$C17*100,"") | I17: =IFERROR(F17/$C17*100,"") | J17: =IF(C17="","",C17=SUM(D17+E17+F17))
B18: DS Fada | C18: =+Population!F17 -> 0 | D18: 244281 | E18: 119176 | F18: 151355 | G18: =IFERROR(D18/$C18*100,"") | H18: =IFERROR(E18/$C18*100,"") | I18: =IFERROR(F18/$C18*100,"") | J18: =IF(C18="","",C18=SUM(D18+E18+F18)) -> FALSE
B19: DS Pama | C19: =+Population!F18 -> 0 | D19: 69497 | E19: 30943 | F19: 40432 | G19: =IFERROR(D19/$C19*100,"") | H19: =IFERROR(E19/$C19*100,"") | I19: =IFERROR(F19/$C19*100,"") | J19: =IF(C19="","",C19=SUM(D19+E19+F19)) -> FALSE
A20: Guiriko | C20: =+Population!F19 -> 0 | D20: =SUM(D21:D29) -> 2089110 | E20: =SUM(E21:E29) -> 288282 | F20: =SUM(F21:F29) -> 296986 | G20: =IFERROR(D20/$C20*100,"") | H20: =IFERROR(E20/$C20*100,"") | I20: =IFERROR(F20/$C20*100,"") | J20: =IF(C20="","",C20=SUM(D20+E20+F20)) -> FALSE
B21: CHU Sanou Souro | C21: =+Population!F20 -> 0 | G21: =IFERROR(D21/$C21*100,"") | H21: =IFERROR(E21/$C21*100,"") | I21: =IFERROR(F21/$C21*100,"") | J21: =IF(C21="","",C21=SUM(D21+E21+F21)) -> TRUE
B22: DS Dafra | C22: =+Population!F21 -> 0 | D22: 498264 | E22: 8725 | F22: 12752 | G22: =IFERROR(D22/$C22*100,"") | H22: =IFERROR(E22/$C22*100,"") | I22: =IFERROR(F22/$C22*100,"") | J22: =IF(C22="","",C22=SUM(D22+E22+F22)) -> FALSE
B23: DS Dande | C23: =+Population!F22 -> 0 | D23: 173216 | E23: 57112 | F23: 33802 | G23: =IFERROR(D23/$C23*100,"") | H23: =IFERROR(E23/$C23*100,"") | I23: =IFERROR(F23/$C23*100,"") | J23: =IF(C23="","",C23=SUM(D23+E23+F23)) -> FALSE
B24: DS Do | C24: =+Population!F23 -> 0 | D24: 686566 | E24: 48477 | F24: 62270 | G24: =IFERROR(D24/$C24*100,"") | H24: =IFERROR(E24/$C24*100,"") | I24: =IFERROR(F24/$C24*100,"") | J24: =IF(C24="","",C24=SUM(D24+E24+F24)) -> FALSE
B25: DS Hounde | C25: =+Population!F24 -> 0 | D25: 309732 | E25: 31939 | F25: 46872 | G25: =IFERROR(D25/$C25*100,"") | H25: =IFERROR(E25/$C25*100,"") | I25: =IFERROR(F25/$C25*100,"") | J25: =IF(C25="","",C25=SUM(D25+E25+F25)) -> FALSE
B26: DS Karangasso Vigue | C26: =+Population!F25 -> 0 | D26: 52074 | E26: 51079 | F26: 43288 | G26: =IFERROR(D26/$C26*100,"") | H26: =IFERROR(E26/$C26*100,"") | I26: =IFERROR(F26/$C26*100,"") | J26: =IF(C26="","",C26=SUM(D26+E26+F26)) -> FALSE
B27: DS Léna | C27: =+Population!F26 -> 0 | D27: 72144 | E27: 8547 | F27: 8343 | G27: =IFERROR(D27/$C27*100,"") | H27: =IFERROR(E27/$C27*100,"") | I27: =IFERROR(F27/$C27*100,"") | J27: =IF(C27="","",C27=SUM(D27+E27+F27)) -> FALSE
B28: DS N'Dorola | C28: =+Population!F27 -> 0 | D28: 102157 | E28: 40779 | F28: 34725 | G28: =IFERROR(D28/$C28*100,"") | H28: =IFERROR(E28/$C28*100,"") | I28: =IFERROR(F28/$C28*100,"") | J28: =IF(C28="","",C28=SUM(D28+E28+F28)) -> FALSE
B29: DS Orodara | C29: =+Population!F28 -> 0 | D29: 194957 | E29: 41624 | F29: 54934 | G29: =IFERROR(D29/$C29*100,"") | H29: =IFERROR(E29/$C29*100,"") | I29: =IFERROR(F29/$C29*100,"") | J29: =IF(C29="","",C29=SUM(D29+E29+F29)) -> FALSE
A30: Kadiogo | C30: =+Population!F29 -> 0 | D30: =SUM(D31:D42) -> 3600935 | E30: =SUM(E31:E42) -> 107431 | F30: =SUM(F31:F42) -> 14774 | G30: =IFERROR(D30/$C30*100,"") | H30: =IFERROR(E30/$C30*100,"") | I30: =IFERROR(F30/$C30*100,"") | J30: =IF(C30="","",C30=SUM(D30+E30+F30)) -> FALSE
B31: CHU Bogodogo | C31: =+Population!F30 -> 0 | G31: =IFERROR(D31/$C31*100,"") | H31: =IFERROR(E31/$C31*100,"") | I31: =IFERROR(F31/$C31*100,"") | J31: =IF(C31="","",C31=SUM(D31+E31+F31)) -> TRUE
B32: CHU Pédiatrique CDG | C32: =+Population!F31 -> 0 | G32: =IFERROR(D32/$C32*100,"") | H32: =IFERROR(E32/$C32*100,"") | I32: =IFERROR(F32/$C32*100,"") | J32: =IF(C32="","",C32=SUM(D32+E32+F32)) -> TRUE
B33: CHU Tengandogo | C33: =+Population!F32 -> 0 | G33: =IFERROR(D33/$C33*100,"") | H33: =IFERROR(E33/$C33*100,"") | I33: =IFERROR(F33/$C33*100,"") | J33: =IF(C33="","",C33=SUM(D33+E33+F33)) -> TRUE
B34: CHU Yalgado | C34: =+Population!F33 -> 0 | G34: =IFERROR(D34/$C34*100,"") | H34: =IFERROR(E34/$C34*100,"") | I34: =IFERROR(F34/$C34*100,"") | J34: =IF(C34="","",C34=SUM(D34+E34+F34)) -> TRUE
B35: Hôpital Paul VI | C35: =+Population!F34 -> 0 | G35: =IFERROR(D35/$C35*100,"") | H35: =IFERROR(E35/$C35*100,"") | I35: =IFERROR(F35/$C35*100,"") | J35: =IF(C35="","",C35=SUM(D35+E35+F35)) -> TRUE
B36: Hôpital Saint Camille | C36: =+Population!F35 -> 0 | G36: =IFERROR(D36/$C36*100,"") | H36: =IFERROR(E36/$C36*100,"") | I36: =IFERROR(F36/$C36*100,"") | J36: =IF(C36="","",C36=SUM(D36+E36+F36)) -> TRUE
B37: Hôpital SCHIPHRA | C37: =+Population!F36 -> 0 | G37: =IFERROR(D37/$C37*100,"") | H37: =IFERROR(E37/$C37*100,"") | I37: =IFERROR(F37/$C37*100,"") | J37: =IF(C37="","",C37=SUM(D37+E37+F37)) -> TRUE
B38: DS Baskuy | C38: =+Population!F37 -> 0 | D38: 184704 | E38: 0 | F38: 0 | G38: =IFERROR(D38/$C38*100,"") | H38: =IFERROR(E38/$C38*100,"") | I38: =IFERROR(F38/$C38*100,"") | J38: =IF(C38="","",C38=SUM(D38+E38+F38)) -> FALSE
B39: DS Bogodogo | C39: =+Population!F38 -> 0 | D39: 1129454 | E39: 29109 | F39: 5823 | G39: =IFERROR(D39/$C39*100,"") | H39: =IFERROR(E39/$C39*100,"") | I39: =IFERROR(F39/$C39*100,"") | J39: =IF(C39="","",C39=SUM(D39+E39+F39)) -> FALSE
B40: DS Boulmiougou | C40: =+Population!F39 -> 0 | D40: 1194422 | E40: 72976 | F40: 8951 | G40: =IFERROR(D40/$C40*100,"") | H40: =IFERROR(E40/$C40*100,"") | I40: =IFERROR(F40/$C40*100,"") | J40: =IF(C40="","",C40=SUM(D40+E40+F40)) -> FALSE
...

Sheet Complétude
A1: Tableau 1.08: Complétude des rapports mensuels des formations sanitaires en 2025
A2: Régions / districts | C2: Formations sanitaires publiques | F2: Formations sanitaires privées | I2: Formations sanitaires publiques et privées
C3: Nombre de rapports attendus | D3: Nombre de rapports saisis | E3: Complétude (%) des rapports dans la base | F3: Nombre de rapports attendus | G3: Nombre de rapports saisis | H3: Complétude (%) des rapports dans la base | I3: Nombre de rapports attendus | J3: Nombre de rapports saisis | K3: Complétude (%) des rapports dans la base | L3: Nombre de rapports saisis à temps | M3: Promptitude (%) des rapports dans la base
A4: Bankui | E4: =IF(C4=0,"",D4/C4*100) | H4: =IF(F4=0,"",G4/F4*100) | I4: =SUM(C4)+SUM(F4) -> 0 | J4: =D4+G4 -> 0 | K4: =IF(I4=0,"",J4/I4*100) | M4: =IF(I4=0,"",L4/I4*100)
B5: CHR Dédougou | E5: =IF(C5=0,"",D5/C5*100) | H5: =IF(F5=0,"",G5/F5*100) | I5: =SUM(C5)+SUM(F5) -> 0 | J5: =D5+G5 -> 0 | K5: =IF(I5=0,"",J5/I5*100) | M5: =IF(I5=0,"",L5/I5*100)
B6: DS Boromo | E6: =IF(C6=0,"",D6/C6*100) | H6: =IF(F6=0,"",G6/F6*100) | I6: =SUM(C6)+SUM(F6) -> 0 | J6: =D6+G6 -> 0 | K6: =IF(I6=0,"",J6/I6*100) | M6: =IF(I6=0,"",L6/I6*100)
B7: DS Dedougou | E7: =IF(C7=0,"",D7/C7*100) | H7: =IF(F7=0,"",G7/F7*100) | I7: =SUM(C7)+SUM(F7) -> 0 | J7: =D7+G7 -> 0 | K7: =IF(I7=0,"",J7/I7*100) | M7: =IF(I7=0,"",L7/I7*100)
B8: DS Solenzo | E8: =IF(C8=0,"",D8/C8*100) | H8: =IF(F8=0,"",G8/F8*100) | I8: =SUM(C8)+SUM(F8) -> 0 | J8: =D8+G8 -> 0 | K8: =IF(I8=0,"",J8/I8*100) | M8: =IF(I8=0,"",L8/I8*100)
A9: Djoro | E9: =IF(C9=0,"",D9/C9*100) | H9: =IF(F9=0,"",G9/F9*100) | I9: =SUM(C9)+SUM(F9) -> 0 | J9: =D9+G9 -> 0 | K9: =IF(I9=0,"",J9/I9*100) | M9: =IF(I9=0,"",L9/I9*100)
B10: CHR Gaoua | E10: =IF(C10=0,"",D10/C10*100) | H10: =IF(F10=0,"",G10/F10*100) | I10: =SUM(C10)+SUM(F10) -> 0 | J10: =D10+G10 -> 0 | K10: =IF(I10=0,"",J10/I10*100) | M10: =IF(I10=0,"",L10/I10*100)
B11: DS Batié | E11: =IF(C11=0,"",D11/C11*100) | H11: =IF(F11=0,"",G11/F11*100) | I11: =SUM(C11)+SUM(F11) -> 0 | J11: =D11+G11 -> 0 | K11: =IF(I11=0,"",J11/I11*100) | M11: =IF(I11=0,"",L11/I11*100)
B12: DS Dano | E12: =IF(C12=0,"",D12/C12*100) | H12: =IF(F12=0,"",G12/F12*100) | I12: =SUM(C12)+SUM(F12) -> 0 | J12: =D12+G12 -> 0 | K12: =IF(I12=0,"",J12/I12*100) | M12: =IF(I12=0,"",L12/I12*100)
B13: DS Diébougou | E13: =IF(C13=0,"",D13/C13*100) | H13: =IF(F13=0,"",G13/F13*100) | I13: =SUM(C13)+SUM(F13) -> 0 | J13: =D13+G13 -> 0 | K13: =IF(I13=0,"",J13/I13*100) | M13: =IF(I13=0,"",L13/I13*100)
B14: DS Gaoua | E14: =IF(C14=0,"",D14/C14*100) | H14: =IF(F14=0,"",G14/F14*100) | I14: =SUM(C14)+SUM(F14) -> 0 | J14: =D14+G14 -> 0 | K14: =IF(I14=0,"",J14/I14*100) | M14: =IF(I14=0,"",L14/I14*100)
B15: DS Kampti | E15: =IF(C15=0,"",D15/C15*100) | H15: =IF(F15=0,"",G15/F15*100) | I15: =SUM(C15)+SUM(F15) -> 0 | J15: =D15+G15 -> 0 | K15: =IF(I15=0,"",J15/I15*100) | M15: =IF(I15=0,"",L15/I15*100)
A16: Goulmou | E16: =IF(C16=0,"",D16/C16*100) | H16: =IF(F16=0,"",G16/F16*100) | I16: =SUM(C16)+SUM(F16) -> 0 | J16: =D16+G16 -> 0 | K16: =IF(I16=0,"",J16/I16*100) | M16: =IF(I16=0,"",L16/I16*100)
B17: CHR Fada N'Gourma | E17: =IF(C17=0,"",D17/C17*100) | H17: =IF(F17=0,"",G17/F17*100) | I17: =SUM(C17)+SUM(F17) -> 0 | J17: =D17+G17 -> 0 | K17: =IF(I17=0,"",J17/I17*100) | M17: =IF(I17=0,"",L17/I17*100)
B18: DS Fada | E18: =IF(C18=0,"",D18/C18*100) | H18: =IF(F18=0,"",G18/F18*100) | I18: =SUM(C18)+SUM(F18) -> 0 | J18: =D18+G18 -> 0 | K18: =IF(I18=0,"",J18/I18*100) | M18: =IF(I18=0,"",L18/I18*100)
B19: DS Pama | E19: =IF(C19=0,"",D19/C19*100) | H19: =IF(F19=0,"",G19/F19*100) | I19: =SUM(C19)+SUM(F19) -> 0 | J19: =D19+G19 -> 0 | K19: =IF(I19=0,"",J19/I19*100) | M19: =IF(I19=0,"",L19/I19*100)
A20: Guiriko | E20: =IF(C20=0,"",D20/C20*100) | H20: =IF(F20=0,"",G20/F20*100) | I20: =SUM(C20)+SUM(F20) -> 0 | J20: =D20+G20 -> 0 | K20: =IF(I20=0,"",J20/I20*100) | M20: =IF(I20=0,"",L20/I20*100)
B21: CHU Sanou Souro | E21: =IF(C21=0,"",D21/C21*100) | H21: =IF(F21=0,"",G21/F21*100) | I21: =SUM(C21)+SUM(F21) -> 0 | J21: =D21+G21 -> 0 | K21: =IF(I21=0,"",J21/I21*100) | M21: =IF(I21=0,"",L21/I21*100)
B22: DS Dafra | E22: =IF(C22=0,"",D22/C22*100) | H22: =IF(F22=0,"",G22/F22*100) | I22: =SUM(C22)+SUM(F22) -> 0 | J22: =D22+G22 -> 0 | K22: =IF(I22=0,"",J22/I22*100) | M22: =IF(I22=0,"",L22/I22*100)
B23: DS Dande | E23: =IF(C23=0,"",D23/C23*100) | H23: =IF(F23=0,"",G23/F23*100) | I23: =SUM(C23)+SUM(F23) -> 0 | J23: =D23+G23 -> 0 | K23: =IF(I23=0,"",J23/I23*100) | M23: =IF(I23=0,"",L23/I23*100)
B24: DS Do | E24: =IF(C24=0,"",D24/C24*100) | H24: =IF(F24=0,"",G24/F24*100) | I24: =SUM(C24)+SUM(F24) -> 0 | J24: =D24+G24 -> 0 | K24: =IF(I24=0,"",J24/I24*100) | M24: =IF(I24=0,"",L24/I24*100)
B25: DS Hounde | E25: =IF(C25=0,"",D25/C25*100) | H25: =IF(F25=0,"",G25/F25*100) | I25: =SUM(C25)+SUM(F25) -> 0 | J25: =D25+G25 -> 0 | K25: =IF(I25=0,"",J25/I25*100) | M25: =IF(I25=0,"",L25/I25*100)
B26: DS Karangasso Vigue | E26: =IF(C26=0,"",D26/C26*100) | H26: =IF(F26=0,"",G26/F26*100) | I26: =SUM(C26)+SUM(F26) -> 0 | J26: =D26+G26 -> 0 | K26: =IF(I26=0,"",J26/I26*100) | M26: =IF(I26=0,"",L26/I26*100)
B27: DS Léna | E27: =IF(C27=0,"",D27/C27*100) | H27: =IF(F27=0,"",G27/F27*100) | I27: =SUM(C27)+SUM(F27) -> 0 | J27: =D27+G27 -> 0 | K27: =IF(I27=0,"",J27/I27*100) | M27: =IF(I27=0,"",L27/I27*100)
B28: DS N'Dorola | E28: =IF(C28=0,"",D28/C28*100) | H28: =IF(F28=0,"",G28/F28*100) | I28: =SUM(C28)+SUM(F28) -> 0 | J28: =D28+G28 -> 0 | K28: =IF(I28=0,"",J28/I28*100) | M28: =IF(I28=0,"",L28/I28*100)
B29: DS Orodara | E29: =IF(C29=0,"",D29/C29*100) | H29: =IF(F29=0,"",G29/F29*100) | I29: =SUM(C29)+SUM(F29) -> 0 | J29: =D29+G29 -> 0 | K29: =IF(I29=0,"",J29/I29*100) | M29: =IF(I29=0,"",L29/I29*100)
A30: Kadiogo | E30: =IF(C30=0,"",D30/C30*100) | H30: =IF(F30=0,"",G30/F30*100) | I30: =SUM(C30)+SUM(F30) -> 0 | J30: =D30+G30 -> 0 | K30: =IF(I30=0,"",J30/I30*100) | M30: =IF(I30=0,"",L30/I30*100)
B31: CHU Bogodogo | E31: =IF(C31=0,"",D31/C31*100) | H31: =IF(F31=0,"",G31/F31*100) | I31: =SUM(C31)+SUM(F31) -> 0 | J31: =D31+G31 -> 0 | K31: =IF(I31=0,"",J31/I31*100) | M31: =IF(I31=0,"",L31/I31*100)
B32: CHU Pédiatrique CDG | E32: =IF(C32=0,"",D32/C32*100) | H32: =IF(F32=0,"",G32/F32*100) | I32: =SUM(C32)+SUM(F32) -> 0 | J32: =D32+G32 -> 0 | K32: =IF(I32=0,"",J32/I32*100) | M32: =IF(I32=0,"",L32/I32*100)
B33: CHU Tengandogo | E33: =IF(C33=0,"",D33/C33*100) | H33: =IF(F33=0,"",G33/F33*100) | I33: =SUM(C33)+SUM(F33) -> 0 | J33: =D33+G33 -> 0 | K33: =IF(I33=0,"",J33/I33*100) | M33: =IF(I33=0,"",L33/I33*100)
B34: CHU Yalgado | E34: =IF(C34=0,"",D34/C34*100) | H34: =IF(F34=0,"",G34/F34*100) | I34: =SUM(C34)+SUM(F34) -> 0 | J34: =D34+G34 -> 0 | K34: =IF(I34=0,"",J34/I34*100) | M34: =IF(I34=0,"",L34/I34*100)
B35: Hôpital Paul VI | E35: =IF(C35=0,"",D35/C35*100) | H35: =IF(F35=0,"",G35/F35*100) | I35: =SUM(C35)+SUM(F35) -> 0 | J35: =D35+G35 -> 0 | K35: =IF(I35=0,"",J35/I35*100) | M35: =IF(I35=0,"",L35/I35*100)
B36: Hôpital Saint Camille | E36: =IF(C36=0,"",D36/C36*100) | H36: =IF(F36=0,"",G36/F36*100) | I36: =SUM(C36)+SUM(F36) -> 0 | J36: =D36+G36 -> 0 | K36: =IF(I36=0,"",J36/I36*100) | M36: =IF(I36=0,"",L36/I36*100)
B37: Hôpital SCHIPHRA | E37: =IF(C37=0,"",D37/C37*100) | H37: =IF(F37=0,"",G37/F37*100) | I37: =SUM(C37)+SUM(F37) -> 0 | J37: =D37+G37 -> 0 | K37: =IF(I37=0,"",J37/I37*100) | M37: =IF(I37=0,"",L37/I37*100)
B38: DS Baskuy | E38: =IF(C38=0,"",D38/C38*100) | H38: =IF(F38=0,"",G38/F38*100) | I38: =SUM(C38)+SUM(F38) -> 0 | J38: =D38+G38 -> 0 | K38: =IF(I38=0,"",J38/I38*100) | M38: =IF(I38=0,"",L38/I38*100)
B39: DS Bogodogo | E39: =IF(C39=0,"",D39/C39*100) | H39: =IF(F39=0,"",G39/F39*100) | I39: =SUM(C39)+SUM(F39) -> 0 | J39: =D39+G39 -> 0 | K39: =IF(I39=0,"",J39/I39*100) | M39: =IF(I39=0,"",L39/I39*100)
B40: DS Boulmiougou | E40: =IF(C40=0,"",D40/C40*100) | H40: =IF(F40=0,"",G40/F40*100) | I40: =SUM(C40)+SUM(F40) -> 0 | J40: =D40+G40 -> 0 | K40: =IF(I40=0,"",J40/I40*100) | M40: =IF(I40=0,"",L40/I40*100)
...

Sheet Sécurité précaire_Publique
A1: Tableau 1.09: Rapports non transmis pour raison d'insécurité par mois des FS publiques en 2025
A2: Régions/Districts | C2: Janv | D2: Févr | E2: Mars | F2: Avr | G2: Mai | H2: Juin | I2: Juil | J2: Août | K2: Sept | L2: Oct | M2: Nov | N2: Déc | O2: Total RMA
A3: Bankui | C3: =SUM(C4:C7) -> 23 | D3: =SUM(D4:D7) -> 23 | E3: =SUM(E4:E7) -> 23 | F3: =SUM(F4:F7) -> 23 | G3: =SUM(G4:G7) -> 22 | H3: =SUM(H4:H7) -> 21 | I3: =SUM(I4:I7) -> 19 | J3: =SUM(J4:J7) -> 18 | ... N3: =SUM(N4:N7) -> 16 | O3: =SUM(C3:N3) -> 236
B4: CHR Dédougou | C4: 0 | D4: 0 | E4: 0 | F4: 0 | G4: 0 | H4: 0 | I4: 0 | J4: 0 | K4: 0 | L4: 0 | M4: 0 | N4: 0 | O4: =SUM(C4:N4) -> 0
B5: DS Boromo | C5: 0 | D5: 0 | E5: 0 | F5: 0 | G5: 0 | H5: 0 | I5: 0 | J5: 0 | K5: 0 | L5: 0 | M5: 0 | N5: 0 | O5: =SUM(C5:N5) -> 0
B6: DS Dedougou | C6: 6 | D6: 6 | E6: 6 | F6: 6 | G6: 6 | H6: 6 | I6: 6 | J6: 6 | K6: 6 | L6: 5 | M6: 5 | N6: 5 | O6: =SUM(C6:N6) -> 69
B7: DS Solenzo | C7: 17 | D7: 17 | E7: 17 | F7: 17 | G7: 16 | H7: 15 | I7: 13 | J7: 12 | K7: 11 | L7: 11 | M7: 10 | N7: 11 | O7: =SUM(C7:N7) -> 167
A8: Djoro | C8: =SUM(C9:C14) -> 1 | D8: =SUM(D9:D14) -> 1 | E8: =SUM(E9:E14) -> 1 | F8: =SUM(F9:F14) -> 1 | G8: =SUM(G9:G14) -> 1 | H8: =SUM(H9:H14) -> 1 | I8: =SUM(I9:I14) -> 1 | J8: =SUM(J9:J14) -> 1 | ... N8: =SUM(N9:N14) -> 1 | O8: =SUM(C8:N8) -> 12
B9: CHR Gaoua | C9: 0 | D9: 0 | E9: 0 | F9: 0 | G9: 0 | H9: 0 | I9: 0 | J9: 0 | K9: 0 | L9: 0 | M9: 0 | N9: 0 | O9: =SUM(C9:N9) -> 0
B10: DS Batié | C10: 0 | D10: 0 | E10: 0 | F10: 0 | G10: 0 | H10: 0 | I10: 0 | J10: 0 | K10: 0 | L10: 0 | M10: 0 | N10: 0 | O10: =SUM(C10:N10) -> 0
B11: DS Dano | C11: 0 | D11: 0 | E11: 0 | F11: 0 | G11: 0 | H11: 0 | I11: 0 | J11: 0 | K11: 0 | L11: 0 | M11: 0 | N11: 0 | O11: =SUM(C11:N11) -> 0
B12: DS Diébougou | C12: 0 | D12: 0 | E12: 0 | F12: 0 | G12: 0 | H12: 0 | I12: 0 | J12: 0 | K12: 0 | L12: 0 | M12: 0 | N12: 0 | O12: =SUM(C12:N12) -> 0
B13: DS Gaoua | C13: 0 | D13: 0 | E13: 0 | F13: 0 | G13: 0 | H13: 0 | I13: 0 | J13: 0 | K13: 0 | L13: 0 | M13: 0 | N13: 0 | O13: =SUM(C13:N13) -> 0
B14: DS Kampti | C14: 1 | D14: 1 | E14: 1 | F14: 1 | G14: 1 | H14: 1 | I14: 1 | J14: 1 | K14: 1 | L14: 1 | M14: 1 | N14: 1 | O14: =SUM(C14:N14) -> 12
A15: Goulmou | C15: =SUM(C16:C18) -> 26 | D15: =SUM(D16:D18) -> 29 | E15: =SUM(E16:E18) -> 30 | F15: =SUM(F16:F18) -> 29 | G15: =SUM(G16:G18) -> 31 | H15: =SUM(H16:H18) -> 31 | I15: =SUM(I16:I18) -> 33 | J15: =SUM(J16:J18) -> 39 | ... N15: =SUM(N16:N18) -> 42 | O15: =SUM(C15:N15) -> 415
B16: CHR Fada N'Gourma | C16: 0 | D16: 0 | E16: 0 | F16: 0 | G16: 0 | H16: 0 | I16: 0 | J16: 0 | K16: 0 | L16: 0 | M16: 0 | N16: 0 | O16: =SUM(C16:N16) -> 0
B17: DS Fada | C17: 17 | D17: 20 | E17: 21 | F17: 20 | G17: 22 | H17: 22 | I17: 24 | J17: 30 | K17: 32 | L17: 33 | M17: 33 | N17: 33 | O17: =SUM(C17:N17) -> 307
B18: DS Pama | C18: 9 | D18: 9 | E18: 9 | F18: 9 | G18: 9 | H18: 9 | I18: 9 | J18: 9 | K18: 9 | L18: 9 | M18: 9 | N18: 9 | O18: =SUM(C18:N18) -> 108
A19: Guiriko | C19: =SUM(C20:C28) -> 9 | D19: =SUM(D20:D28) -> 9 | E19: =SUM(E20:E28) -> 9 | F19: =SUM(F20:F28) -> 9 | G19: =SUM(G20:G28) -> 9 | H19: =SUM(H20:H28) -> 9 | I19: =SUM(I20:I28) -> 7 | J19: =SUM(J20:J28) -> 7 | ... N19: =SUM(N20:N28) -> 7 | O19: =SUM(C19:N19) -> 96
B20: CHU Sanou Souro | C20: 0 | D20: 0 | E20: 0 | F20: 0 | G20: 0 | H20: 0 | I20: 0 | J20: 0 | K20: 0 | L20: 0 | M20: 0 | N20: 0 | O20: =SUM(C20:N20) -> 0
B21: DS Dafra | C21: 0 | D21: 0 | E21: 0 | F21: 0 | G21: 0 | H21: 0 | I21: 0 | J21: 0 | K21: 0 | L21: 0 | M21: 0 | N21: 0 | O21: =SUM(C21:N21) -> 0
B22: DS Dande | C22: 2 | D22: 2 | E22: 2 | F22: 2 | G22: 2 | H22: 2 | I22: 1 | J22: 1 | K22: 1 | L22: 1 | M22: 1 | N22: 1 | O22: =SUM(C22:N22) -> 18
B23: DS Do | C23: 0 | D23: 0 | E23: 0 | F23: 0 | G23: 0 | H23: 0 | I23: 0 | J23: 0 | K23: 0 | L23: 0 | M23: 0 | N23: 0 | O23: =SUM(C23:N23) -> 0
B24: DS Hounde | C24: 1 | D24: 1 | E24: 1 | F24: 1 | G24: 1 | H24: 1 | I24: 1 | J24: 1 | K24: 1 | L24: 1 | M24: 1 | N24: 1 | O24: =SUM(C24:N24) -> 12
B25: DS Karangasso Vigue | C25: 0 | D25: 0 | E25: 0 | F25: 0 | G25: 0 | H25: 0 | I25: 0 | J25: 0 | K25: 0 | L25: 0 | M25: 0 | N25: 0 | O25: =SUM(C25:N25) -> 0
B26: DS Léna | C26: 0 | D26: 0 | E26: 0 | F26: 0 | G26: 0 | H26: 0 | I26: 0 | J26: 0 | K26: 0 | L26: 0 | M26: 0 | N26: 0 | O26: =SUM(C26:N26) -> 0
B27: DS N'Dorola | C27: 3 | D27: 3 | E27: 3 | F27: 3 | G27: 3 | H27: 3 | I27: 3 | J27: 3 | K27: 3 | L27: 3 | M27: 3 | N27: 3 | O27: =SUM(C27:N27) -> 36
B28: DS Orodara | C28: 3 | D28: 3 | E28: 3 | F28: 3 | G28: 3 | H28: 3 | I28: 2 | J28: 2 | K28: 2 | L28: 2 | M28: 2 | N28: 2 | O28: =SUM(C28:N28) -> 30
A29: Kadiogo | C29: =SUM(C30:C41) -> 0 | D29: =SUM(D30:D41) -> 0 | E29: =SUM(E30:E41) -> 0 | F29: =SUM(F30:F41) -> 0 | G29: =SUM(G30:G41) -> 0 | H29: =SUM(H30:H41) -> 0 | I29: =SUM(I30:I41) -> 0 | J29: =SUM(J30:J41) -> 0 | ... N29: =SUM(N30:N41) -> 0 | O29: =SUM(C29:N29) -> 0
B30: CHU Bogodogo | C30: 0 | D30: 0 | E30: 0 | F30: 0 | G30: 0 | H30: 0 | I30: 0 | J30: 0 | K30: 0 | L30: 0 | M30: 0 | N30: 0 | O30: =SUM(C30:N30) -> 0
B31: CHU Pédiatrique CDG | C31: 0 | D31: 0 | E31: 0 | F31: 0 | G31: 0 | H31: 0 | I31: 0 | J31: 0 | K31: 0 | L31: 0 | M31: 0 | N31: 0 | O31: =SUM(C31:N31) -> 0
B32: CHU Tengandogo | C32: 0 | D32: 0 | E32: 0 | F32: 0 | G32: 0 | H32: 0 | I32: 0 | J32: 0 | K32: 0 | L32: 0 | M32: 0 | N32: 0 | O32: =SUM(C32:N32) -> 0
B33: CHU Yalgado | C33: 0 | D33: 0 | E33: 0 | F33: 0 | G33: 0 | H33: 0 | I33: 0 | J33: 0 | K33: 0 | L33: 0 | M33: 0 | N33: 0 | O33: =SUM(C33:N33) -> 0
B34: Hôpital Paul VI | O34: =SUM(C34:N34) -> 0
B35: Hôpital Saint Camille | O35: =SUM(C35:N35) -> 0
B36: Hôpital SCHIPHRA | O36: =SUM(C36:N36) -> 0
B37: DS Baskuy | C37: 0 | D37: 0 | E37: 0 | F37: 0 | G37: 0 | H37: 0 | I37: 0 | J37: 0 | K37: 0 | L37: 0 | M37: 0 | N37: 0 | O37: =SUM(C37:N37) -> 0
B38: DS Bogodogo | C38: 0 | D38: 0 | E38: 0 | F38: 0 | G38: 0 | H38: 0 | I38: 0 | J38: 0 | K38: 0 | L38: 0 | M38: 0 | N38: 0 | O38: =SUM(C38:N38) -> 0
B39: DS Boulmiougou | C39: 0 | D39: 0 | E39: 0 | F39: 0 | G39: 0 | H39: 0 | I39: 0 | J39: 0 | K39: 0 | L39: 0 | M39: 0 | N39: 0 | O39: =SUM(C39:N39) -> 0
B40: DS Nongr-Massom | C40: 0 | D40: 0 | E40: 0 | F40: 0 | G40: 0 | H40: 0 | I40: 0 | J40: 0 | K40: 0 | L40: 0 | M40: 0 | N40: 0 | O40: =SUM(C40:N40) -> 0
...

Sheet Sécurité précaire_Privee
A1: Tableau 1.10: Rapports non transmis pour raison d'insécurité par mois des FS privées en 2025
A2: Régions/Districts | C2: Janv | D2: Févr | E2: Mars | F2: Avr | G2: Mai | H2: Juin | I2: Juil | J2: Août | K2: Sept | L2: Oct | M2: Nov | N2: Déc | O2: Total RMA
A3: Bankui | C3: =SUM(C4:C7) -> 0 | D3: =SUM(D4:D7) -> 0 | E3: =SUM(E4:E7) -> 0 | F3: =SUM(F4:F7) -> 0 | G3: =SUM(G4:G7) -> 0 | H3: =SUM(H4:H7) -> 0 | I3: =SUM(I4:I7) -> 0 | J3: =SUM(J4:J7) -> 0 | ... N3: =SUM(N4:N7) -> 0 | O3: =SUM(C3:N3) -> 0
B4: CHR Dédougou | C4: 0 | D4: 0 | E4: 0 | F4: 0 | G4: 0 | H4: 0 | I4: 0 | J4: 0 | K4: 0 | L4: 0 | M4: 0 | N4: 0 | O4: =SUM(C4:N4) -> 0
B5: DS Boromo | C5: 0 | D5: 0 | E5: 0 | F5: 0 | G5: 0 | H5: 0 | I5: 0 | J5: 0 | K5: 0 | L5: 0 | M5: 0 | N5: 0 | O5: =SUM(C5:N5) -> 0
B6: DS Dedougou | C6: 0 | D6: 0 | E6: 0 | F6: 0 | G6: 0 | H6: 0 | I6: 0 | J6: 0 | K6: 0 | L6: 0 | M6: 0 | N6: 0 | O6: =SUM(C6:N6) -> 0
B7: DS Solenzo | C7: 0 | D7: 0 | E7: 0 | F7: 0 | G7: 0 | H7: 0 | I7: 0 | J7: 0 | K7: 0 | L7: 0 | M7: 0 | N7: 0 | O7: =SUM(C7:N7) -> 0
A8: Djoro | C8: 0 | D8: 0 | E8: 0 | F8: 0 | G8: 0 | H8: 0 | I8: 0 | J8: 0 | K8: 0 | L8: 0 | M8: 0 | N8: 0 | O8: =SUM(C8:N8) -> 0
B9: CHR Gaoua | C9: 0 | D9: 0 | E9: 0 | F9: 0 | G9: 0 | H9: 0 | I9: 0 | J9: 0 | K9: 0 | L9: 0 | M9: 0 | N9: 0 | O9: =SUM(C9:N9) -> 0
B10: DS Batié | C10: 0 | D10: 0 | E10: 0 | F10: 0 | G10: 0 | H10: 0 | I10: 0 | J10: 0 | K10: 0 | L10: 0 | M10: 0 | N10: 0 | O10: =SUM(C10:N10) -> 0
B11: DS Dano | C11: 0 | D11: 0 | E11: 0 | F11: 0 | G11: 0 | H11: 0 | I11: 0 | J11: 0 | K11: 0 | L11: 0 | M11: 0 | N11: 0 | O11: =SUM(C11:N11) -> 0
B12: DS Diébougou | C12: 0 | D12: 0 | E12: 0 | F12: 0 | G12: 0 | H12: 0 | I12: 0 | J12: 0 | K12: 0 | L12: 0 | M12: 0 | N12: 0 | O12: =SUM(C12:N12) -> 0
B13: DS Gaoua | C13: 0 | D13: 0 | E13: 0 | F13: 0 | G13: 0 | H13: 0 | I13: 0 | J13: 0 | K13: 0 | L13: 0 | M13: 0 | N13: 0 | O13: =SUM(C13:N13) -> 0
B14: DS Kampti | C14: 0 | D14: 0 | E14: 0 | F14: 0 | G14: 0 | H14: 0 | I14: 0 | J14: 0 | K14: 0 | L14: 0 | M14: 0 | N14: 0 | O14: =SUM(C14:N14) -> 0
A15: Goulmou | C15: =SUM(C16:C18) -> 2 | D15: =SUM(D16:D18) -> 2 | E15: =SUM(E16:E18) -> 2 | F15: =SUM(F16:F18) -> 2 | G15: =SUM(G16:G18) -> 2 | H15: =SUM(H16:H18) -> 2 | I15: =SUM(I16:I18) -> 2 | J15: =SUM(J16:J18) -> 2 | ... N15: =SUM(N16:N18) -> 2 | O15: =SUM(C15:N15) -> 24
B16: CHR Fada N'Gourma | C16: 0 | D16: 0 | E16: 0 | F16: 0 | G16: 0 | H16: 0 | I16: 0 | J16: 0 | K16: 0 | L16: 0 | M16: 0 | N16: 0 | O16: =SUM(C16:N16) -> 0
B17: DS Fada | C17: 1 | D17: 1 | E17: 1 | F17: 1 | G17: 1 | H17: 1 | I17: 1 | J17: 1 | K17: 1 | L17: 1 | M17: 1 | N17: 1 | O17: =SUM(C17:N17) -> 12
B18: DS Pama | C18: 1 | D18: 1 | E18: 1 | F18: 1 | G18: 1 | H18: 1 | I18: 1 | J18: 1 | K18: 1 | L18: 1 | M18: 1 | N18: 1 | O18: =SUM(C18:N18) -> 12
A19: Guiriko | C19: =SUM(C20:C28) -> 0 | D19: =SUM(D20:D28) -> 0 | E19: =SUM(E20:E28) -> 0 | F19: =SUM(F20:F28) -> 0 | G19: =SUM(G20:G28) -> 0 | H19: =SUM(H20:H28) -> 0 | I19: =SUM(I20:I28) -> 0 | J19: =SUM(J20:J28) -> 0 | ... N19: =SUM(N20:N28) -> 0 | O19: =SUM(C19:N19) -> 0
B20: CHU Sanou Souro | C20: 0 | D20: 0 | E20: 0 | F20: 0 | G20: 0 | H20: 0 | I20: 0 | J20: 0 | K20: 0 | L20: 0 | M20: 0 | N20: 0 | O20: =SUM(C20:N20) -> 0
B21: DS Dafra | C21: 0 | D21: 0 | E21: 0 | F21: 0 | G21: 0 | H21: 0 | I21: 0 | J21: 0 | K21: 0 | L21: 0 | M21: 0 | N21: 0 | O21: =SUM(C21:N21) -> 0
B22: DS Dande | C22: 0 | D22: 0 | E22: 0 | F22: 0 | G22: 0 | H22: 0 | I22: 0 | J22: 0 | K22: 0 | L22: 0 | M22: 0 | N22: 0 | O22: =SUM(C22:N22) -> 0
B23: DS Do | C23: 0 | D23: 0 | E23: 0 | F23: 0 | G23: 0 | H23: 0 | I23: 0 | J23: 0 | K23: 0 | L23: 0 | M23: 0 | N23: 0 | O23: =SUM(C23:N23) -> 0
B24: DS Hounde | C24: 0 | D24: 0 | E24: 0 | F24: 0 | G24: 0 | H24: 0 | I24: 0 | J24: 0 | K24: 0 | L24: 0 | M24: 0 | N24: 0 | O24: =SUM(C24:N24) -> 0
B25: DS Karangasso Vigue | C25: 0 | D25: 0 | E25: 0 | F25: 0 | G25: 0 | H25: 0 | I25: 0 | J25: 0 | K25: 0 | L25: 0 | M25: 0 | N25: 0 | O25: =SUM(C25:N25) -> 0
B26: DS Léna | C26: 0 | D26: 0 | E26: 0 | F26: 0 | G26: 0 | H26: 0 | I26: 0 | J26: 0 | K26: 0 | L26: 0 | M26: 0 | N26: 0 | O26: =SUM(C26:N26) -> 0
B27: DS N'Dorola | C27: 0 | D27: 0 | E27: 0 | F27: 0 | G27: 0 | H27: 0 | I27: 0 | J27: 0 | K27: 0 | L27: 0 | M27: 0 | N27: 0 | O27: =SUM(C27:N27) -> 0
B28: DS Orodara | C28: 0 | D28: 0 | E28: 0 | F28: 0 | G28: 0 | H28: 0 | I28: 0 | J28: 0 | K28: 0 | L28: 0 | M28: 0 | N28: 0 | O28: =SUM(C28:N28) -> 0
A29: Kadiogo | C29: =SUM(C30:C41) -> 0 | D29: =SUM(D30:D41) -> 0 | E29: =SUM(E30:E41) -> 0 | F29: =SUM(F30:F41) -> 0 | G29: =SUM(G30:G41) -> 0 | H29: =SUM(H30:H41) -> 0 | I29: =SUM(I30:I41) -> 0 | J29: =SUM(J30:J41) -> 0 | ... N29: =SUM(N30:N41) -> 0 | O29: =SUM(C29:N29) -> 0
B30: CHU Bogodogo | C30: 0 | D30: 0 | E30: 0 | F30: 0 | G30: 0 | H30: 0 | I30: 0 | J30: 0 | K30: 0 | L30: 0 | M30: 0 | N30: 0 | O30: =SUM(C30:N30) -> 0
B31: CHU Pédiatrique CDG | C31: 0 | D31: 0 | E31: 0 | F31: 0 | G31: 0 | H31: 0 | I31: 0 | J31: 0 | K31: 0 | L31: 0 | M31: 0 | N31: 0 | O31: =SUM(C31:N31) -> 0
B32: CHU Tengandogo | C32: 0 | D32: 0 | E32: 0 | F32: 0 | G32: 0 | H32: 0 | I32: 0 | J32: 0 | K32: 0 | L32: 0 | M32: 0 | N32: 0 | O32: =SUM(C32:N32) -> 0
B33: CHU Yalgado | C33: 0 | D33: 0 | E33: 0 | F33: 0 | G33: 0 | H33: 0 | I33: 0 | J33: 0 | K33: 0 | L33: 0 | M33: 0 | N33: 0 | O33: =SUM(C33:N33) -> 0
B34: Hôpital Paul VI | C34: 0 | D34: 0 | E34: 0 | F34: 0 | G34: 0 | H34: 0 | I34: 0 | J34: 0 | K34: 0 | L34: 0 | M34: 0 | N34: 0 | O34: =SUM(C34:N34) -> 0
B35: Hôpital Saint Camille | C35: 0 | D35: 0 | E35: 0 | F35: 0 | G35: 0 | H35: 0 | I35: 0 | J35: 0 | K35: 0 | L35: 0 | M35: 0 | N35: 0 | O35: =SUM(C35:N35) -> 0
B36: Hôpital SCHIPHRA | C36: 0 | D36: 0 | E36: 0 | F36: 0 | G36: 0 | H36: 0 | I36: 0 | J36: 0 | K36: 0 | L36: 0 | M36: 0 | N36: 0 | O36: =SUM(C36:N36) -> 0
B37: DS Baskuy | C37: 0 | D37: 0 | E37: 0 | F37: 0 | G37: 0 | H37: 0 | I37: 0 | J37: 0 | K37: 0 | L37: 0 | M37: 0 | N37: 0 | O37: =SUM(C37:N37) -> 0
B38: DS Bogodogo | C38: 0 | D38: 0 | E38: 0 | F38: 0 | G38: 0 | H38: 0 | I38: 0 | J38: 0 | K38: 0 | L38: 0 | M38: 0 | N38: 0 | O38: =SUM(C38:N38) -> 0
B39: DS Boulmiougou | C39: 0 | D39: 0 | E39: 0 | F39: 0 | G39: 0 | H39: 0 | I39: 0 | J39: 0 | K39: 0 | L39: 0 | M39: 0 | N39: 0 | O39: =SUM(C39:N39) -> 0
B40: DS Nongr-Massom | C40: 0 | D40: 0 | E40: 0 | F40: 0 | G40: 0 | H40: 0 | I40: 0 | J40: 0 | K40: 0 | L40: 0 | M40: 0 | N40: 0 | O40: =SUM(C40:N40) -> 0
...

Sheet ComplétudeCorrige
A1: Tableau 1.11: complétude des rapports mensuels des formations sanitaires prenant en compte la non transmission de rapport pour fait d'insecurité en 2025
A2: Régions / districts | C2: Formations sanitaires publiques | F2: Formations sanitaires privées | I2: Formations sanitaires publiques et privées
C3: Nombre de rapports attendus | D3: Nombre de rapports saisis | E3: Complétude (%) des rapports dans la base | F3: Nombre de rapports attendus | G3: Nombre de rapports saisis | H3: Complétude (%) des rapports dans la base | I3: Nombre de rapports attendus | J3: Nombre de rapports saisis | K3: Complétude (%) des rapports dans la base | L3: Nombre de rapports saisis à temps | M3: Promptitude (%) des rapports dans la base
A4: Bankui | C4: =Complétude!C4-'Sécurité précaire_Publique'!O3 -> -236 | D4: =Complétude!D4 -> 0 | E4: =IFERROR(D4/C4*100,"") -> 0 | F4: =Complétude!F4-'Sécurité précaire_Privee'!O3 -> 0 | G4: =Complétude!G4 -> 0 | H4: =IFERROR(G4/F4*100,"") | I4: =C4+F4 -> -236 | J4: =D4+G4 -> 0 | K4: =IFERROR(J4/I4*100,"") -> 0 | L4: =Complétude!L4 -> 0 | M4: =IFERROR(L4/I4*100,"") -> 0
B5: CHR Dédougou | C5: =Complétude!C5-'Sécurité précaire_Publique'!O4 -> 0 | D5: =Complétude!D5 -> 0 | E5: =IFERROR(D5/C5*100,"") | F5: =Complétude!F5-'Sécurité précaire_Privee'!O4 -> 0 | G5: =Complétude!G5 -> 0 | H5: =IFERROR(G5/F5*100,"") | I5: =C5+F5 -> 0 | J5: =D5+G5 -> 0 | K5: =IFERROR(J5/I5*100,"") | L5: =Complétude!L5 -> 0 | M5: =IFERROR(L5/I5*100,"")
B6: DS Boromo | C6: =Complétude!C6-'Sécurité précaire_Publique'!O5 -> 0 | D6: =Complétude!D6 -> 0 | E6: =IFERROR(D6/C6*100,"") | F6: =Complétude!F6-'Sécurité précaire_Privee'!O5 -> 0 | G6: =Complétude!G6 -> 0 | H6: =IFERROR(G6/F6*100,"") | I6: =C6+F6 -> 0 | J6: =D6+G6 -> 0 | K6: =IFERROR(J6/I6*100,"") | L6: =Complétude!L6 -> 0 | M6: =IFERROR(L6/I6*100,"")
B7: DS Dedougou | C7: =Complétude!C7-'Sécurité précaire_Publique'!O6 -> -69 | D7: =Complétude!D7 -> 0 | E7: =IFERROR(D7/C7*100,"") -> 0 | F7: =Complétude!F7-'Sécurité précaire_Privee'!O6 -> 0 | G7: =Complétude!G7 -> 0 | H7: =IFERROR(G7/F7*100,"") | I7: =C7+F7 -> -69 | J7: =D7+G7 -> 0 | K7: =IFERROR(J7/I7*100,"") -> 0 | L7: =Complétude!L7 -> 0 | M7: =IFERROR(L7/I7*100,"") -> 0
B8: DS Solenzo | C8: =Complétude!C8-'Sécurité précaire_Publique'!O7 -> -167 | D8: =Complétude!D8 -> 0 | E8: =IFERROR(D8/C8*100,"") -> 0 | F8: =Complétude!F8-'Sécurité précaire_Privee'!O7 -> 0 | G8: =Complétude!G8 -> 0 | H8: =IFERROR(G8/F8*100,"") | I8: =C8+F8 -> -167 | J8: =D8+G8 -> 0 | K8: =IFERROR(J8/I8*100,"") -> 0 | L8: =Complétude!L8 -> 0 | M8: =IFERROR(L8/I8*100,"") -> 0
A9: Djoro | C9: =Complétude!C9-'Sécurité précaire_Publique'!O8 -> -12 | D9: =Complétude!D9 -> 0 | E9: =IFERROR(D9/C9*100,"") -> 0 | F9: =Complétude!F9-'Sécurité précaire_Privee'!O8 -> 0 | G9: =Complétude!G9 -> 0 | H9: =IFERROR(G9/F9*100,"") | I9: =C9+F9 -> -12 | J9: =D9+G9 -> 0 | K9: =IFERROR(J9/I9*100,"") -> 0 | L9: =Complétude!L9 -> 0 | M9: =IFERROR(L9/I9*100,"") -> 0
B10: CHR Gaoua | C10: =Complétude!C10-'Sécurité précaire_Publique'!O9 -> 0 | D10: =Complétude!D10 -> 0 | E10: =IFERROR(D10/C10*100,"") | F10: =Complétude!F10-'Sécurité précaire_Privee'!O9 -> 0 | G10: =Complétude!G10 -> 0 | H10: =IFERROR(G10/F10*100,"") | I10: =C10+F10 -> 0 | J10: =D10+G10 -> 0 | K10: =IFERROR(J10/I10*100,"") | L10: =Complétude!L10 -> 0 | M10: =IFERROR(L10/I10*100,"")
B11: DS Batié | C11: =Complétude!C11-'Sécurité précaire_Publique'!O10 -> 0 | D11: =Complétude!D11 -> 0 | E11: =IFERROR(D11/C11*100,"") | F11: =Complétude!F11-'Sécurité précaire_Privee'!O10 -> 0 | G11: =Complétude!G11 -> 0 | H11: =IFERROR(G11/F11*100,"") | I11: =C11+F11 -> 0 | J11: =D11+G11 -> 0 | K11: =IFERROR(J11/I11*100,"") | L11: =Complétude!L11 -> 0 | M11: =IFERROR(L11/I11*100,"")
B12: DS Dano | C12: =Complétude!C12-'Sécurité précaire_Publique'!O11 -> 0 | D12: =Complétude!D12 -> 0 | E12: =IFERROR(D12/C12*100,"") | F12: =Complétude!F12-'Sécurité précaire_Privee'!O11 -> 0 | G12: =Complétude!G12 -> 0 | H12: =IFERROR(G12/F12*100,"") | I12: =C12+F12 -> 0 | J12: =D12+G12 -> 0 | K12: =IFERROR(J12/I12*100,"") | L12: =Complétude!L12 -> 0 | M12: =IFERROR(L12/I12*100,"")
B13: DS Diébougou | C13: =Complétude!C13-'Sécurité précaire_Publique'!O12 -> 0 | D13: =Complétude!D13 -> 0 | E13: =IFERROR(D13/C13*100,"") | F13: =Complétude!F13-'Sécurité précaire_Privee'!O12 -> 0 | G13: =Complétude!G13 -> 0 | H13: =IFERROR(G13/F13*100,"") | I13: =C13+F13 -> 0 | J13: =D13+G13 -> 0 | K13: =IFERROR(J13/I13*100,"") | L13: =Complétude!L13 -> 0 | M13: =IFERROR(L13/I13*100,"")
B14: DS Gaoua | C14: =Complétude!C14-'Sécurité précaire_Publique'!O13 -> 0 | D14: =Complétude!D14 -> 0 | E14: =IFERROR(D14/C14*100,"") | F14: =Complétude!F14-'Sécurité précaire_Privee'!O13 -> 0 | G14: =Complétude!G14 -> 0 | H14: =IFERROR(G14/F14*100,"") | I14: =C14+F14 -> 0 | J14: =D14+G14 -> 0 | K14: =IFERROR(J14/I14*100,"") | L14: =Complétude!L14 -> 0 | M14: =IFERROR(L14/I14*100,"")
B15: DS Kampti | C15: =Complétude!C15-'Sécurité précaire_Publique'!O14 -> -12 | D15: =Complétude!D15 -> 0 | E15: =IFERROR(D15/C15*100,"") -> 0 | F15: =Complétude!F15-'Sécurité précaire_Privee'!O14 -> 0 | G15: =Complétude!G15 -> 0 | H15: =IFERROR(G15/F15*100,"") | I15: =C15+F15 -> -12 | J15: =D15+G15 -> 0 | K15: =IFERROR(J15/I15*100,"") -> 0 | L15: =Complétude!L15 -> 0 | M15: =IFERROR(L15/I15*100,"") -> 0
A16: Goulmou | C16: =Complétude!C16-'Sécurité précaire_Publique'!O15 -> -415 | D16: =Complétude!D16 -> 0 | E16: =IFERROR(D16/C16*100,"") -> 0 | F16: =Complétude!F16-'Sécurité précaire_Privee'!O15 -> -24 | G16: =Complétude!G16 -> 0 | H16: =IFERROR(G16/F16*100,"") -> 0 | I16: =C16+F16 -> -439 | J16: =D16+G16 -> 0 | K16: =IFERROR(J16/I16*100,"") -> 0 | L16: =Complétude!L16 -> 0 | M16: =IFERROR(L16/I16*100,"") -> 0
B17: CHR Fada N'Gourma | C17: =Complétude!C17-'Sécurité précaire_Publique'!O16 -> 0 | D17: =Complétude!D17 -> 0 | E17: =IFERROR(D17/C17*100,"") | F17: =Complétude!F17-'Sécurité précaire_Privee'!O16 -> 0 | G17: =Complétude!G17 -> 0 | H17: =IFERROR(G17/F17*100,"") | I17: =C17+F17 -> 0 | J17: =D17+G17 -> 0 | K17: =IFERROR(J17/I17*100,"") | L17: =Complétude!L17 -> 0 | M17: =IFERROR(L17/I17*100,"")
B18: DS Fada | C18: =Complétude!C18-'Sécurité précaire_Publique'!O17 -> -307 | D18: =Complétude!D18 -> 0 | E18: =IFERROR(D18/C18*100,"") -> 0 | F18: =Complétude!F18-'Sécurité précaire_Privee'!O17 -> -12 | G18: =Complétude!G18 -> 0 | H18: =IFERROR(G18/F18*100,"") -> 0 | I18: =C18+F18 -> -319 | J18: =D18+G18 -> 0 | K18: =IFERROR(J18/I18*100,"") -> 0 | L18: =Complétude!L18 -> 0 | M18: =IFERROR(L18/I18*100,"") -> 0
B19: DS Pama | C19: =Complétude!C19-'Sécurité précaire_Publique'!O18 -> -108 | D19: =Complétude!D19 -> 0 | E19: =IFERROR(D19/C19*100,"") -> 0 | F19: =Complétude!F19-'Sécurité précaire_Privee'!O18 -> -12 | G19: =Complétude!G19 -> 0 | H19: =IFERROR(G19/F19*100,"") -> 0 | I19: =C19+F19 -> -120 | J19: =D19+G19 -> 0 | K19: =IFERROR(J19/I19*100,"") -> 0 | L19: =Complétude!L19 -> 0 | M19: =IFERROR(L19/I19*100,"") -> 0
A20: Guiriko | C20: =Complétude!C20-'Sécurité précaire_Publique'!O19 -> -96 | D20: =Complétude!D20 -> 0 | E20: =IFERROR(D20/C20*100,"") -> 0 | F20: =Complétude!F20-'Sécurité précaire_Privee'!O19 -> 0 | G20: =Complétude!G20 -> 0 | H20: =IFERROR(G20/F20*100,"") | I20: =C20+F20 -> -96 | J20: =D20+G20 -> 0 | K20: =IFERROR(J20/I20*100,"") -> 0 | L20: =Complétude!L20 -> 0 | M20: =IFERROR(L20/I20*100,"") -> 0
B21: CHU Sanou Souro | C21: =Complétude!C21-'Sécurité précaire_Publique'!O20 -> 0 | D21: =Complétude!D21 -> 0 | E21: =IFERROR(D21/C21*100,"") | F21: =Complétude!F21-'Sécurité précaire_Privee'!O20 -> 0 | G21: =Complétude!G21 -> 0 | H21: =IFERROR(G21/F21*100,"") | I21: =C21+F21 -> 0 | J21: =D21+G21 -> 0 | K21: =IFERROR(J21/I21*100,"") | L21: =Complétude!L21 -> 0 | M21: =IFERROR(L21/I21*100,"")
B22: DS Dafra | C22: =Complétude!C22-'Sécurité précaire_Publique'!O21 -> 0 | D22: =Complétude!D22 -> 0 | E22: =IFERROR(D22/C22*100,"") | F22: =Complétude!F22-'Sécurité précaire_Privee'!O21 -> 0 | G22: =Complétude!G22 -> 0 | H22: =IFERROR(G22/F22*100,"") | I22: =C22+F22 -> 0 | J22: =D22+G22 -> 0 | K22: =IFERROR(J22/I22*100,"") | L22: =Complétude!L22 -> 0 | M22: =IFERROR(L22/I22*100,"")
